Workbook

Sheet Instructions
A1: CareerSphere AI: matching evaluation kit
A2: Question: does CareerSphere's match rule agree with human judgment better than plain keyword matching?
A4: How to label (each of 3 people, separately)
A5: 1. Open the "Label pairs" sheet only. Do not look at "Predictions" or "Results" until all labels are in, so the scores cannot influence you.
A6: 2. For each row, read the student's skills and CGPA and the job's required skills and CGPA cutoff.
A7: 3. Answer: "Would I advise this student to apply now, with a fair chance of being shortlisted?" Type Y or N in your yellow column.
A8: 4. Judge the fit yourself. Don't count skills mechanically; use what a placement mentor would think.
A9: 5. Labeler 1, 2 and 3 should be different people (for example you and two teammates or seniors).
A11: Example of a filled row (not part of the data):
A12: Student skills: Java, SQL, Git | CGPA 7.8 | Job: Software Engineer Trainee needs Java, SQL, Git, Data Structures, min CGPA 6.5 | Labels: Y, Y, N -> Majority Y
A14: Cells you edit
A15: Yellow cells only: the three label columns in "Label pairs", and the two settings in "Results" (match threshold and keyword minimum).
... A30: Report whatever the numbers turn out to be, including if the baseline wins on some measure. An honest result is worth more than a flattering one.

Sheet Label pairs
A1: Pair | B1: Student | C1: Branch | D1: CGPA | E1: Student skills | F1: Job | G1: Company | H1: Required skills | I1: Min CGPA | J1: Labeler 1 (Y/N) | K1: Labeler 2 (Y/N) | L1: Labeler 3 (Y/N) | M1: Human majority
A2: P01 | B2: Lokesh Reddy | C2: IT | D2: 7.2 | E2: Git, Java, SQL | F2: Data Analyst | G2: Nimbus Technologies | H2: Excel, Power BI, Python, SQL | I2: None | M2: =IF(COUNTA(J2:L2)<3,"",IF(COUNTIF(J2:L2,"Y")>=2,"Y","N"))
A3: P02 | B3: Karthik Rao | C3: ECE | D3: 7.9 | E3: Data Structures, Git, Java, SQL | F3: Microservices Developer | G3: Nimbus Technologies | H3: Docker, Java, Microservices, REST APIs, Spring Boot | I3: 7.5 | M3: =IF(COUNTA(J3:L3)<3,"",IF(COUNTIF(J3:L3,"Y")>=2,"Y","N"))
A4: P03 | B4: Manasa Gowda | C4: CSE | D4: 8 | E4: Java, REST APIs, SQL | F4: QA Automation Engineer | G4: BrightPath Labs | H4: Git, Java, Selenium, SQL | I4: None | M4: =IF(COUNTA(J4:L4)<3,"",IF(COUNTIF(J4:L4,"Y")>=2,"Y","N"))
A5: P04 | B5: Harsha Vardhan | C5: CSE | D5: 7.5 | E5: Git, Java, Spring Boot | F5: QA Automation Engineer | G5: BrightPath Labs | H5: Git, Java, Selenium, SQL | I5: None | M5: =IF(COUNTA(J5:L5)<3,"",IF(COUNTIF(J5:L5,"Y")>=2,"Y","N"))
A6: P05 | B6: Aarav Sharma | C6: CSE | D6: 8.2 | E6: CSS, Git, HTML, Java, JavaScript, Python, SQL | F6: Java Backend Developer | G6: Nimbus Technologies | H6: Git, Java, REST APIs, Spring Boot, SQL | I6: None | M6: =IF(COUNTA(J6:L6)<3,"",IF(COUNTIF(J6:L6,"Y")>=2,"Y","N"))
A7: P06 | B7: Meera Pillai | C7: CSE | D7: 8.4 | E7: Git, Java, Spring Boot, SQL | F7: Java Backend Developer | G7: Nimbus Technologies | H7: Git, Java, REST APIs, Spring Boot, SQL | I7: None | M7: =IF(COUNTA(J7:L7)<3,"",IF(COUNTIF(J7:L7,"Y")>=2,"Y","N"))
A8: P07 | B8: Aditya Kulkarni | C8: CSE | D8: 7.8 | E8: Git, HTML, Java, SQL | F8: Java Backend Developer | G8: Nimbus Technologies | H8: Git, Java, REST APIs, Spring Boot, SQL | I8: None | M8: =IF(COUNTA(J8:L8)<3,"",IF(COUNTIF(J8:L8,"Y")>=2,"Y","N"))
A9: P08 | B9: Arjun Patel | C9: EEE | D9: 7.2 | E9: Java, Selenium, SQL | F9: Java Backend Developer | G9: Nimbus Technologies | H9: Git, Java, REST APIs, Spring Boot, SQL | I9: None | M9: =IF(COUNTA(J9:L9)<3,"",IF(COUNTIF(J9:L9,"Y")>=2,"Y","N"))
A10: P09 | B10: Harsha Vardhan | C10: CSE | D10: 7.5 | E10: Git, Java, Spring Boot | F10: Full Stack Developer | G10: BrightPath Labs | H10: Java, JavaScript, React, Spring Boot, SQL | I10: None | M10: =IF(COUNTA(J10:L10)<3,"",IF(COUNTIF(J10:L10,"Y")>=2,"Y","N"))
A11: P10 | B11: Arjun Patel | C11: EEE | D11: 7.2 | E11: Java, Selenium, SQL | F11: Java Developer Intern | G11: BrightPath Labs | H11: Git, Java, Spring Boot | I11: None | M11: =IF(COUNTA(J11:L11)<3,"",IF(COUNTIF(J11:L11,"Y")>=2,"Y","N"))
A12: P11 | B12: Tarun Agarwal | C12: CSE | D12: 7.7 | E12: Java, Selenium, SQL | F12: QA Automation Engineer | G12: BrightPath Labs | H12: Git, Java, Selenium, SQL | I12: None | M12: =IF(COUNTA(J12:L12)<3,"",IF(COUNTIF(J12:L12,"Y")>=2,"Y","N"))
A13: P12 | B13: Divya Menon | C13: CSE | D13: 8.9 | E13: Excel, Power BI, Python, SQL | F13: QA Automation Engineer | G13: BrightPath Labs | H13: Git, Java, Selenium, SQL | I13: None | M13: =IF(COUNTA(J13:L13)<3,"",IF(COUNTIF(J13:L13,"Y")>=2,"Y","N"))
A14: P13 | B14: Gayathri Iyer | C14: IT | D14: 9 | E14: Data Structures, Java, SQL | F14: QA Automation Engineer | G14: BrightPath Labs | H14: Git, Java, Selenium, SQL | I14: None | M14: =IF(COUNTA(J14:L14)<3,"",IF(COUNTIF(J14:L14,"Y")>=2,"Y","N"))
A15: P14 | B15: Harsha Vardhan | C15: CSE | D15: 7.5 | E15: Git, Java, Spring Boot | F15: Java Developer Intern | G15: BrightPath Labs | H15: Git, Java, Spring Boot | I15: None | M15: =IF(COUNTA(J15:L15)<3,"",IF(COUNTIF(J15:L15,"Y")>=2,"Y","N"))
A16: P15 | B16: Sameer Ali | C16: IT | D16: 7.3 | E16: CSS, Git, HTML | F16: Cloud & DevOps Engineer | G16: Nimbus Technologies | H16: AWS, Docker, Git, Kubernetes, Linux | I16: None | M16: =IF(COUNTA(J16:L16)<3,"",IF(COUNTIF(J16:L16,"Y")>=2,"Y","N"))
A17: P16 | B17: Kavya Menon | C17: CSE | D17: 8.8 | E17: Pandas, Python, SQL | F17: Backend Engineer - Payments | G17: Nimbus Technologies | H17: Docker, Java, Spring Boot, SQL | I17: 7 | M17: =IF(COUNTA(J17:L17)<3,"",IF(COUNTIF(J17:L17,"Y")>=2,"Y","N"))
A18: P17 | B18: Harsha Vardhan | C18: CSE | D18: 7.5 | E18: Git, Java, Spring Boot | F18: Web Developer | G18: Nimbus Technologies | H18: CSS, Git, HTML, JavaScript | I18: None | M18: =IF(COUNTA(J18:L18)<3,"",IF(COUNTIF(J18:L18,"Y")>=2,"Y","N"))
A19: P18 | B19: Chirag Mehta | C19: CSE | D19: 7.1 | E19: Data Structures, Git, Java | F19: Java Developer Intern | G19: BrightPath Labs | H19: Git, Java, Spring Boot | I19: None | M19: =IF(COUNTA(J19:L19)<3,"",IF(COUNTIF(J19:L19,"Y")>=2,"Y","N"))
A20: P19 | B20: Aditya Kulkarni | C20: CSE | D20: 7.8 | E20: Git, HTML, Java, SQL | F20: Software Engineer Trainee | G20: Nimbus Technologies | H20: Data Structures, Git, Java, SQL | I20: 6.5 | M20: =IF(COUNTA(J20:L20)<3,"",IF(COUNTIF(J20:L20,"Y")>=2,"Y","N"))
A21: P20 | B21: Isha Kapoor | C21: CSE | D21: 8.3 | E21: CSS, Git, HTML, JavaScript | F21: Web Developer | G21: Nimbus Technologies | H21: CSS, Git, HTML, JavaScript | I21: None | M21: =IF(COUNTA(J21:L21)<3,"",IF(COUNTIF(J21:L21,"Y")>=2,"Y","N"))
A22: P21 | B22: Rahul Joshi | C22: IT | D22: 6.9 | E22: Git, Java | F22: QA Automation Engineer | G22: BrightPath Labs | H22: Git, Java, Selenium, SQL | I22: None | M22: =IF(COUNTA(J22:L22)<3,"",IF(COUNTIF(J22:L22,"Y")>=2,"Y","N"))
A23: P22 | B23: Uma Krishnan | C23: IT | D23: 8.2 | E23: Excel, Power BI, SQL | F23: Full Stack Developer | G23: BrightPath Labs | H23: Java, JavaScript, React, Spring Boot, SQL | I23: None | M23: =IF(COUNTA(J23:L23)<3,"",IF(COUNTIF(J23:L23,"Y")>=2,"Y","N"))
A24: P23 | B24: Pooja Shetty | C24: CSE | D24: 8.4 | E24: CSS, HTML, JavaScript, React | F24: Frontend Developer | G24: BrightPath Labs | H24: CSS, HTML, JavaScript, React, TypeScript | I24: None | M24: =IF(COUNTA(J24:L24)<3,"",IF(COUNTIF(J24:L24,"Y")>=2,"Y","N"))
A25: P24 | B25: Tarun Agarwal | C25: CSE | D25: 7.7 | E25: Java, Selenium, SQL | F25: Frontend Developer | G25: BrightPath Labs | H25: CSS, HTML, JavaScript, React, TypeScript | I25: None | M25: =IF(COUNTA(J25:L25)<3,"",IF(COUNTIF(J25:L25,"Y")>=2,"Y","N"))
A26: P25 | B26: Rohan Gupta | C26: IT | D26: 7.4 | E26: CSS, Git, HTML, JavaScript, React | F26: Frontend Developer | G26: BrightPath Labs | H26: CSS, HTML, JavaScript, React, TypeScript | I26: None | M26: =IF(COUNTA(J26:L26)<3,"",IF(COUNTIF(J26:L26,"Y")>=2,"Y","N"))
A27: P26 | B27: Ananya Reddy | C27: CSE | D27: 9.1 | E27: Docker, Git, Java, REST APIs, Spring Boot, SQL | F27: QA Automation Engineer | G27: BrightPath Labs | H27: Git, Java, Selenium, SQL | I27: None | M27: =IF(COUNTA(J27:L27)<3,"",IF(COUNTIF(J27:L27,"Y")>=2,"Y","N"))
A28: P27 | B28: Meera Pillai | C28: CSE | D28: 8.4 | E28: Git, Java, Spring Boot, SQL | F28: QA Automation Engineer | G28: BrightPath Labs | H28: Git, Java, Selenium, SQL | I28: None | M28: =IF(COUNTA(J28:L28)<3,"",IF(COUNTIF(J28:L28,"Y")>=2,"Y","N"))
A29: P28 | B29: Varun Pillai | C29: CSE | D29: 7.4 | E29: Data Structures, Git, Java, SQL | F29: Web Developer | G29: Nimbus Technologies | H29: CSS, Git, HTML, JavaScript | I29: None | M29: =IF(COUNTA(J29:L29)<3,"",IF(COUNTIF(J29:L29,"Y")>=2,"Y","N"))
A30: P29 | B30: Sameer Ali | C30: IT | D30: 7.3 | E30: CSS, Git, HTML | F30: Machine Learning Intern | G30: BrightPath Labs | H30: Machine Learning, Pandas, Python, SQL | I30: 8.5 | M30: =IF(COUNTA(J30:L30)<3,"",IF(COUNTIF(J30:L30,"Y")>=2,"Y","N"))
A31: P30 | B31: Akash Verma | C31: EEE | D31: 6.7 | E31: Java, SQL | F31: Backend Engineer - Payments | G31: Nimbus Technologies | H31: Docker, Java, Spring Boot, SQL | I31: 7 | M31: =IF(COUNTA(J31:L31)<3,"",IF(COUNTIF(J31:L31,"Y")>=2,"Y","N"))
A32: P31 | B32: Chirag Mehta | C32: CSE | D32: 7.1 | E32: Data Structures, Git, Java | F32: Software Engineer Trainee | G32: Nimbus Technologies | H32: Data Structures, Git, Java, SQL | I32: 6.5 | M32: =IF(COUNTA(J32:L32)<3,"",IF(COUNTIF(J32:L32,"Y")>=2,"Y","N"))
A33: P32 | B33: Ananya Reddy | C33: CSE | D33: 9.1 | E33: Docker, Git, Java, REST APIs, Spring Boot, SQL | F33: Full Stack Developer | G33: BrightPath Labs | H33: Java, JavaScript, React, Spring Boot, SQL | I33: None | M33: =IF(COUNTA(J33:L33)<3,"",IF(COUNTIF(J33:L33,"Y")>=2,"Y","N"))
A34: P33 | B34: Farhan Sheikh | C34: CSE | D34: 6.8 | E34: CSS, HTML, JavaScript | F34: Web Developer | G34: Nimbus Technologies | H34: CSS, Git, HTML, JavaScript | I34: None | M34: =IF(COUNTA(J34:L34)<3,"",IF(COUNTIF(J34:L34,"Y")>=2,"Y","N"))
A35: P34 | B35: Farhan Sheikh | C35: CSE | D35: 6.8 | E35: CSS, HTML, JavaScript | F35: Machine Learning Intern | G35: BrightPath Labs | H35: Machine Learning, Pandas, Python, SQL | I35: 8.5 | M35: =IF(COUNTA(J35:L35)<3,"",IF(COUNTIF(J35:L35,"Y")>=2,"Y","N"))
A36: P35 | B36: Harsha Vardhan | C36: CSE | D36: 7.5 | E36: Git, Java, Spring Boot | F36: Software Engineer Trainee | G36: Nimbus Technologies | H36: Data Structures, Git, Java, SQL | I36: 6.5 | M36: =IF(COUNTA(J36:L36)<3,"",IF(COUNTIF(J36:L36,"Y")>=2,"Y","N"))
A37: P36 | B37: Uma Krishnan | C37: IT | D37: 8.2 | E37: Excel, Power BI, SQL | F37: Frontend Developer | G37: BrightPath Labs | H37: CSS, HTML, JavaScript, React, TypeScript | I37: None | M37: =IF(COUNTA(J37:L37)<3,"",IF(COUNTIF(J37:L37,"Y")>=2,"Y","N"))
A38: P37 | B38: Manasa Gowda | C38: CSE | D38: 8 | E38: Java, REST APIs, SQL | F38: Software Engineer Trainee | G38: Nimbus Technologies | H38: Data Structures, Git, Java, SQL | I38: 6.5 | M38: =IF(COUNTA(J38:L38)<3,"",IF(COUNTIF(J38:L38,"Y")>=2,"Y","N"))
A39: P38 | B39: Nandini Hegde | C39: CSE | D39: 8.7 | E39: Java, Spring Boot, SQL | F39: Backend Engineer - Payments | G39: Nimbus Technologies | H39: Docker, Java, Spring Boot, SQL | I39: 7 | M39: =IF(COUNTA(J39:L39)<3,"",IF(COUNTIF(J39:L39,"Y")>=2,"Y","N"))
A40: P39 | B40: Isha Kapoor | C40: CSE | D40: 8.3 | E40: CSS, Git, HTML, JavaScript | F40: Frontend Developer | G40: BrightPath Labs | H40: CSS, HTML, JavaScript, React, TypeScript | I40: None | M40: =IF(COUNTA(J40:L40)<3,"",IF(COUNTIF(J40:L40,"Y")>=2,"Y","N"))
...

Sheet Predictions
A1: Pair | B1: Student | C1: Job | D1: CareerSphere score (%) | E1: Meets CGPA cutoff | F1: CareerSphere predicts fit | G1: Shared skills | H1: Keyword baseline predicts fit | I1: Human majority | J1: CareerSphere agrees | K1: Baseline agrees
A2: ='Label pairs'!A2 -> P01 | B2: ='Label pairs'!B2 -> Lokesh Reddy | C2: ='Label pairs'!F2 -> Data Analyst | D2: 25 | E2: Y | F2: =IF(AND(D2>=Results!$C$5,E2="Y"),"Y","N") -> N | G2: 1 | H2: =IF(G2>=Results!$C$6,"Y","N") -> N | I2: ='Label pairs'!M2 | J2: =IF(I2="","",IF(F2=I2,1,0)) | K2: =IF(I2="","",IF(H2=I2,1,0))
A3: ='Label pairs'!A3 -> P02 | B3: ='Label pairs'!B3 -> Karthik Rao | C3: ='Label pairs'!F3 -> Microservices Developer | D3: 20 | E3: Y | F3: =IF(AND(D3>=Results!$C$5,E3="Y"),"Y","N") -> N | G3: 1 | H3: =IF(G3>=Results!$C$6,"Y","N") -> N | I3: ='Label pairs'!M3 | J3: =IF(I3="","",IF(F3=I3,1,0)) | K3: =IF(I3="","",IF(H3=I3,1,0))
A4: ='Label pairs'!A4 -> P03 | B4: ='Label pairs'!B4 -> Manasa Gowda | C4: ='Label pairs'!F4 -> QA Automation Engineer | D4: 50 | E4: Y | F4: =IF(AND(D4>=Results!$C$5,E4="Y"),"Y","N") -> N | G4: 2 | H4: =IF(G4>=Results!$C$6,"Y","N") -> Y | I4: ='Label pairs'!M4 | J4: =IF(I4="","",IF(F4=I4,1,0)) | K4: =IF(I4="","",IF(H4=I4,1,0))
A5: ='Label pairs'!A5 -> P04 | B5: ='Label pairs'!B5 -> Harsha Vardhan | C5: ='Label pairs'!F5 -> QA Automation Engineer | D5: 50 | E5: Y | F5: =IF(AND(D5>=Results!$C$5,E5="Y"),"Y","N") -> N | G5: 2 | H5: =IF(G5>=Results!$C$6,"Y","N") -> Y | I5: ='Label pairs'!M5 | J5: =IF(I5="","",IF(F5=I5,1,0)) | K5: =IF(I5="","",IF(H5=I5,1,0))
A6: ='Label pairs'!A6 -> P05 | B6: ='Label pairs'!B6 -> Aarav Sharma | C6: ='Label pairs'!F6 -> Java Backend Developer | D6: 60 | E6: Y | F6: =IF(AND(D6>=Results!$C$5,E6="Y"),"Y","N") -> N | G6: 3 | H6: =IF(G6>=Results!$C$6,"Y","N") -> Y | I6: ='Label pairs'!M6 | J6: =IF(I6="","",IF(F6=I6,1,0)) | K6: =IF(I6="","",IF(H6=I6,1,0))
A7: ='Label pairs'!A7 -> P06 | B7: ='Label pairs'!B7 -> Meera Pillai | C7: ='Label pairs'!F7 -> Java Backend Developer | D7: 80 | E7: Y | F7: =IF(AND(D7>=Results!$C$5,E7="Y"),"Y","N") -> Y | G7: 4 | H7: =IF(G7>=Results!$C$6,"Y","N") -> Y | I7: ='Label pairs'!M7 | J7: =IF(I7="","",IF(F7=I7,1,0)) | K7: =IF(I7="","",IF(H7=I7,1,0))
A8: ='Label pairs'!A8 -> P07 | B8: ='Label pairs'!B8 -> Aditya Kulkarni | C8: ='Label pairs'!F8 -> Java Backend Developer | D8: 60 | E8: Y | F8: =IF(AND(D8>=Results!$C$5,E8="Y"),"Y","N") -> N | G8: 3 | H8: =IF(G8>=Results!$C$6,"Y","N") -> Y | I8: ='Label pairs'!M8 | J8: =IF(I8="","",IF(F8=I8,1,0)) | K8: =IF(I8="","",IF(H8=I8,1,0))
A9: ='Label pairs'!A9 -> P08 | B9: ='Label pairs'!B9 -> Arjun Patel | C9: ='Label pairs'!F9 -> Java Backend Developer | D9: 40 | E9: Y | F9: =IF(AND(D9>=Results!$C$5,E9="Y"),"Y","N") -> N | G9: 2 | H9: =IF(G9>=Results!$C$6,"Y","N") -> Y | I9: ='Label pairs'!M9 | J9: =IF(I9="","",IF(F9=I9,1,0)) | K9: =IF(I9="","",IF(H9=I9,1,0))
A10: ='Label pairs'!A10 -> P09 | B10: ='Label pairs'!B10 -> Harsha Vardhan | C10: ='Label pairs'!F10 -> Full Stack Developer | D10: 40 | E10: Y | F10: =IF(AND(D10>=Results!$C$5,E10="Y"),"Y","N") -> N | G10: 2 | H10: =IF(G10>=Results!$C$6,"Y","N") -> Y | I10: ='Label pairs'!M10 | J10: =IF(I10="","",IF(F10=I10,1,0)) | K10: =IF(I10="","",IF(H10=I10,1,0))
A11: ='Label pairs'!A11 -> P10 | B11: ='Label pairs'!B11 -> Arjun Patel | C11: ='Label pairs'!F11 -> Java Developer Intern | D11: 33 | E11: Y | F11: =IF(AND(D11>=Results!$C$5,E11="Y"),"Y","N") -> N | G11: 1 | H11: =IF(G11>=Results!$C$6,"Y","N") -> N | I11: ='Label pairs'!M11 | J11: =IF(I11="","",IF(F11=I11,1,0)) | K11: =IF(I11="","",IF(H11=I11,1,0))
A12: ='Label pairs'!A12 -> P11 | B12: ='Label pairs'!B12 -> Tarun Agarwal | C12: ='Label pairs'!F12 -> QA Automation Engineer | D12: 75 | E12: Y | F12: =IF(AND(D12>=Results!$C$5,E12="Y"),"Y","N") -> Y | G12: 3 | H12: =IF(G12>=Results!$C$6,"Y","N") -> Y | I12: ='Label pairs'!M12 | J12: =IF(I12="","",IF(F12=I12,1,0)) | K12: =IF(I12="","",IF(H12=I12,1,0))
A13: ='Label pairs'!A13 -> P12 | B13: ='Label pairs'!B13 -> Divya Menon | C13: ='Label pairs'!F13 -> QA Automation Engineer | D13: 25 | E13: Y | F13: =IF(AND(D13>=Results!$C$5,E13="Y"),"Y","N") -> N | G13: 1 | H13: =IF(G13>=Results!$C$6,"Y","N") -> N | I13: ='Label pairs'!M13 | J13: =IF(I13="","",IF(F13=I13,1,0)) | K13: =IF(I13="","",IF(H13=I13,1,0))
... A61: ='Label pairs'!A61 -> P60 | B61: ='Label pairs'!B61 -> Arjun Patel | C61: ='Label pairs'!F61 -> Full Stack Developer | D61: 40 | E61: Y | F61: =IF(AND(D61>=Results!$C$5,E61="Y"),"Y","N") -> N | G61: 2 | H61: =IF(G61>=Results!$C$6,"Y","N") -> Y | I61: ='Label pairs'!M61 | J61: =IF(I61="","",IF(F61=I61,1,0)) | K61: =IF(I61="","",IF(H61=I61,1,0))

Sheet Results
B2: CareerSphere vs keyword matching
B4: Settings
B5: CareerSphere match threshold (%) | C5: 70 | E5: Same 70% rule as the app. Change to test other thresholds.
B6: Keyword baseline: minimum shared skills | C6: 2 | E6: Try 1 or 3 to see how sensitive the baseline is.
B8: Pairs with all three labels | C8: =COUNTIF(Predictions!$I$2:$I$61,"Y")+COUNTIF(Predictions!$I$2:$I$61,"N") -> 0
B9: Of which humans call a fit | C9: =COUNTIF(Predictions!$I$2:$I$61,"Y") -> 0
B10: All three labelers agreed | C10: =IF(C8=0,"-",SUMPRODUCT(--('Label pairs'!$M$2:$M$61<>""),((('Label pairs'!$J$2:$J$61="Y")+('Label pairs'!$K$2:$K$61="Y")+('Label pairs'!$L$2:$L$61="Y"))=0)+((('Label pairs'!$J$2:$J$61="Y")+('Label pairs'!$K$2:$K$61="Y")+('Label pairs'!$L$2:$L$61="Y"))=3))/C8) -> - | E10: Share of labeled pairs where all three people gave the same answer.
B12: Measure | C12: CareerSphere | D12: Keyword baseline | E12: Meaning
B13: Accuracy | C13: =IF($C$8=0,"-",(COUNTIFS(Predictions!$F$2:$F$61,"Y",Predictions!$I$2:$I$61,"Y")+COUNTIFS(Predictions!$F$2:$F$61,"N",Predictions!$I$2:$I$61,"N"))/$C$8) -> - | D13: =IF($C$8=0,"-",(COUNTIFS(Predictions!$H$2:$H$61,"Y",Predictions!$I$2:$I$61,"Y")+COUNTIFS(Predictions!$H$2:$H$61,"N",Predictions!$I$2:$I$61,"N"))/$C$8) -> - | E13: Agrees with the human majority
B14: Precision | C14: =IF((COUNTIFS(Predictions!$F$2:$F$61,"Y",Predictions!$I$2:$I$61,"Y")+COUNTIFS(Predictions!$F$2:$F$61,"Y",Predictions!$I$2:$I$61,"N"))=0,"-",COUNTIFS(Predictions!$F$2:$F$61,"Y",Predictions!$I$2:$I$61,"Y")/(COUNTIFS(Predictions!$F$2:$F$61,"Y",Predictions!$I$2:$I$61,"Y")+COUNTIFS(Predictions!$F$2:$F$61,"Y",Predictions!$I$2:$I$61,"N"))) -> - | D14: =IF((COUNTIFS(Predictions!$H$2:$H$61,"Y",Predictions!$I$2:$I$61,"Y")+COUNTIFS(Predictions!$H$2:$H$61,"Y",Predictions!$I$2:$I$61,"N"))=0,"-",COUNTIFS(Predictions!$H$2:$H$61,"Y",Predictions!$I$2:$I$61,"Y")/(COUNTIFS(Predictions!$H$2:$H$61,"Y",Predictions!$I$2:$I$61,"Y")+COUNTIFS(Predictions!$H$2:$H$61,"Y",Predictions!$I$2:$I$61,"N"))) -> - | E14: When it says "fit", how often humans agree
B15: Recall | C15: =IF((COUNTIFS(Predictions!$F$2:$F$61,"Y",Predictions!$I$2:$I$61,"Y")+COUNTIFS(Predictions!$F$2:$F$61,"N",Predictions!$I$2:$I$61,"Y"))=0,"-",COUNTIFS(Predictions!$F$2:$F$61,"Y",Predictions!$I$2:$I$61,"Y")/(COUNTIFS(Predictions!$F$2:$F$61,"Y",Predictions!$I$2:$I$61,"Y")+COUNTIFS(Predictions!$F$2:$F$61,"N",Predictions!$I$2:$I$61,"Y"))) -> - | D15: =IF((COUNTIFS(Predictions!$H$2:$H$61,"Y",Predictions!$I$2:$I$61,"Y")+COUNTIFS(Predictions!$H$2:$H$61,"N",Predictions!$I$2:$I$61,"Y"))=0,"-",COUNTIFS(Predictions!$H$2:$H$61,"Y",Predictions!$I$2:$I$61,"Y")/(COUNTIFS(Predictions!$H$2:$H$61,"Y",Predictions!$I$2:$I$61,"Y")+COUNTIFS(Predictions!$H$2:$H$61,"N",Predictions!$I$2:$I$61,"Y"))) -> - | E15: Of the real fits, how many it finds
B16: F1 score | C16: =IF(OR(C14="-",C15="-"),"-",IF((C14+C15)=0,0,2*C14*C15/(C14+C15))) -> - | D16: =IF(OR(D14="-",D15="-"),"-",IF((D14+D15)=0,0,2*D14*D15/(D14+D15))) -> - | E16: Balance of precision and recall
B17: True fits found (TP) | C17: =COUNTIFS(Predictions!$F$2:$F$61,"Y",Predictions!$I$2:$I$61,"Y") -> 0 | D17: =COUNTIFS(Predictions!$H$2:$H$61,"Y",Predictions!$I$2:$I$61,"Y") -> 0
B18: False alarms (FP) | C18: =COUNTIFS(Predictions!$F$2:$F$61,"Y",Predictions!$I$2:$I$61,"N") -> 0 | D18: =COUNTIFS(Predictions!$H$2:$H$61,"Y",Predictions!$I$2:$I$61,"N") -> 0 | E18: Students it would wrongly encourage to apply
B19: Missed fits (FN) | C19: =COUNTIFS(Predictions!$F$2:$F$61,"N",Predictions!$I$2:$I$61,"Y") -> 0 | D19: =COUNTIFS(Predictions!$H$2:$H$61,"N",Predictions!$I$2:$I$61,"Y") -> 0
B20: Correct rejections (TN) | C20: =COUNTIFS(Predictions!$F$2:$F$61,"N",Predictions!$I$2:$I$61,"N") -> 0 | D20: =COUNTIFS(Predictions!$H$2:$H$61,"N",Predictions!$I$2:$I$61,"N") -> 0
B22: Results stay "-" until the three label columns are filled in.
